Workbook

Sheet Sold
AD1: =COUNT(Sold[DATE])
B2: LEASE NO. | C2: AGENCY | D2: TYPE | E2: INTEREST | F2: ADDRESS | G2: CITY | H2: STATE | I2: LAND | J2: BUILT | K2: SF LEASED | L2: RBA | M2: GOV OCCP | N2: GROSS | O2: GROSS/SF | P2: NOI | Q2: NET/SF | R2: COM | S2: EXP | T2: TERMN | U2: TERM | V2: FIRM | W2: EXPENSES | X2: BUMPS | Y2: RENEWAL OPTIONS | Z2: SOLD PRICE | AA2: SOLD/SF | AB2: SOLD CAP | AC2: ZCF | AD2: DATE | AE2: SELLER | AF2: L. BROKER | AG2: BUYER | AH2: Bstate | AI2: Type2 | AJ2: P. BROKER | AK2: DEVELOPER | AL2: INITIAL PRICE | AM2: INITIAL CAP | AN2: % of Int Ach | AO2: LAST PRICE | AP2: LAST CAP | AQ2: BID-ASK SPREAD | AR2: PRICE CHG | AS2: ON MARKET | AT2: DOM

Sheet Ownership
B2: LEASE NO. | C2: NEW | D2: LOC. CODE | E2: Date | F2: RENEWED | G2: AGENCY | H2: Rep. Agency | I2: Reduce TF | J2: INTEREST | K2: ADDRESS | L2: CITY | M2: STATE | N2: LAND | O2: BUILT | P2: BTS | Q2: SF LEASED | R2: RBA | S2: OCCP | T2: GSA OCCP | U2: GROSS | V2: GROSS/SF | W2: FUTURE/SF | X2: CAGR | Y2: NOI | Z2: NET/SF | AA2: Tenure at Com | AB2: #ofRenewals | AC2: ORG. OCC. | AD2: COM | AE2: EXP | AF2: TERMN | AG2: Last | AH2: Term | AI2: Firm | AJ2: T-Rem | AK2: F-Rem | AL2: EXPS | AM2: OPTS | AN2: EST SIZE | AO2: RECORDED | AP2: TRUE OWNER | AQ2: LAST LL | AR2: COMP | AS2: DEVELOPER

Sheet Inventory
B2: Lease Num | C2: Old | D2: Location Code | E2: City | F2: County | G2: Address | H2: State | I2: ZipCode | J2: Latitude | K2: Longitude | L2: Field Office Name | M2: Cen Bus Unit Ind | N2: Lease Effective | O2: Lease Expiration | P2: Termination Right Date | Q2: Latest Action affecting Term | R2: Fully Serviced | S2: Lease Agreement RSF | T2: Lease Structured Parking | U2: Lease Surface parking | V2: Percent Building | W2: Current Annual Rent | X2: Percent Office | Y2: Percent Warehouse | Z2: Percent Special | AA2: Renewal Option Term left | AB2: Renewal Options Left | AC2: Lessor name

Sheet All Charts
BE1: =AVERAGE(BE24:BE145) | BJ1: =AVERAGE(BJ24:BJ340) | BM1: =AVERAGE(BM24:BM364) | BN1: =AVERAGE(BN24:BN364)
B2: Quarter | C2: Date | D2: Transactions (ttm) | E2: Average Deal Size (ttm) | F2: Monthly Volume | G2: Transaction Volume (ttm) | H2: Trans. Vol. (ttm) | I2: yoy Change (%) | J2: Upper Quartile Cap Rate (ttm) | K2: Lower Quartile Cap Rate (ttm) | L2: Average Cap Rate (ttm) | M2: NM Average Cap (ttm) | N2: Non-NM Average Cap (ttm) | O2: 10+ Year Cap (ttm) | P2: 6 to 10 Year Cap (ttm) | Q2: Less than 5 Year Cap (ttm) | R2: Outside Firm Term (ttm) | S2: Private Volume (ttm) | T2: Public Listed/REIT Volume (ttm) | U2: Cross-Border Volume (ttm) | V2: Institutional Volume (ttm) | W2: Federal Cap | X2: State Cap | Y2: Municipal Cap | Z2: Private Count (ttm) | AA2: Public Listed/REIT Count (ttm) | AB2: Cross-Border Count (ttm) | AC2: Institutional Count (ttm) | AD2: DOM | AE2: % of Ask | AF2: Last Ask | AG2: Bid-Ask Spread | AH2: 10-Year Treasury Yield | AI2: Low Assumed Loan Constant | AJ2: High Assumed Loan Constant | AK2: Price Change (ttm) | AL2: 8+ Year Firm Ask (ttm) | AM2: 8+ Year Firm Price Change (ttm) | AN2: First Generation Lease Commencements (ttm) | AO2: Renewed Leases (ttm) | AP2: Succeeding/Superseding Leases (ttm) | AQ2: Expired Leases (ttm) | AR2: Terminated Leases (ttm) | AS2: Net Change (ttm) | AT2: Total Current Leases (ttm) | AU2: Leases Extended (ttm) | AV2: Footprint Reduced (ttm) | AW2: Leases Expired (ttm) | AX2: Leases Up for Renewal (ttm) | AY2: Leases In Firm Term (ttm) | AZ2: Leases Outside Firm (ttm) | BA2: Leases Terminated (ttm) | BB2: Renewal Rent/SF | BC2: Upper Quartile | BD2: Lower Quartile | BE2: Average Renewal Rent CAGR | BF2: Tenure at Renewal | BG2: Average Lease Term | BH2: Renewal Count | BI2: Avg. Rent | BJ2: Valuation Index | BK2: YOY Change (%)2 | BL2: Expenses PSF (ttm) | BM2: Cash Return Index | BN2: Leveraged Return Index | BO2: CPI
B3: Q2-2025 | C3: 45838 | D3: =COUNTIFS(Sold[DATE],">"&EDATE(Charts[[#This Row],[Date]],-12),Sold[DATE],"<="&Charts[[#This Row],[Date]]) | E3: =AVERAGEIFS(Sold[SOLD PRICE],Sold[DATE],">"&EDATE(Charts[[#This Row],[Date]],-12),Sold[DATE],"<="&Charts[[#This Row],[Date]]) | F3: =SUMIFS(Sold[SOLD PRICE],Sold[DATE],">"&EDATE(Charts[[#This Row],[Date]],-1),Sold[DATE],"<="&Charts[[#This Row],[Date]]) | G3: =SUMIFS(Sold[SOLD PRICE],Sold[DATE],">"&EDATE(Charts[[#This Row],[Date]],-12),Sold[DATE],"<="&Charts[[#This Row],[Date]]) | H3: =Charts[[#This Row],[Average Deal Size (ttm)]]*Charts[[#This Row],[Transactions (ttm)]] | I3: =(Charts[[#This Row],[Trans. Vol. (ttm)]]-H15)/H15 | J3: {=PERCENTILE(IF(Sold[DATE]>EDATE(Charts[[#This Row],[Date]],-12),IF(Sold[DATE]<=Charts[[#This Row],[Date]],IF(Sold[SOLD CAP]<>"",Sold[SOLD CAP]))),0.75)} | K3: {=PERCENTILE(IF(Sold[DATE]>EDATE(Charts[[#This Row],[Date]],-12),IF(Sold[DATE]<=Charts[[#This Row],[Date]],IF(Sold[SOLD CAP]<>"",Sold[SOLD CAP]))),0.25)} | L3: =AVERAGEIFS(Sold[SOLD CAP],Sold[DATE],">"&EDATE(Charts[[#This Row],[Date]],-12),Sold[DATE],"<="&Charts[[#This Row],[Date]]) | M3: =IFERROR(AVERAGEIFS(Sold[SOLD CAP],Sold[DATE],">"&EDATE(Charts[[#This Row],[Date]],-12),Sold[DATE],"<="&Charts[[#This Row],[Date]],Sold[L. BROKER],"*sjc*",Sold[SOLD CAP],"<=.09"),M8) | N3: =IF(Charts[[#This Row],[Average Cap Rate (ttm)]]>(AVERAGEIFS(Sold[SOLD CAP],Sold[L. BROKER],"<>*",Sold[L. BROKER],"<>*sjc*",Sold[DATE],">"&EDATE(Charts[[#This Row],[Date]],-12),Sold[DATE],"<="&Charts[[#This Row],[Date]])),Charts[[#This Row],[Average Cap Rate (ttm)]],AVERAGEIFS(Sold[SOLD CAP],Sold[L. BROKER],"<>*",Sold[L. BROKER],"<>*sjc*",Sold[DATE],">"&EDATE(Charts[[#This Row],[Date]],-12),Sold[DATE],"<="&Charts[[#This Row],[Date]])) | O3: =IFERROR(AVERAGEIFS(Sold[SOLD CAP],Sold[FIRM],">="&10,Sold[DATE],">"&EDATE(Charts[[#This Row],[Date]],-12),Sold[DATE],"<="&Charts[[#This Row],[Date]]),#REF!) | P3: =IFERROR(AVERAGEIFS(Sold[SOLD CAP],Sold[FIRM],">="&6,Sold[FIRM],"<"&10,Sold[DATE],">"&EDATE(Charts[[#This Row],[Date]],-12),Sold[DATE],"<="&Charts[[#This Row],[Date]]),#REF!) | Q3: =IFERROR(AVERAGEIFS(Sold[SOLD CAP],Sold[FIRM],"<"&6,Sold[DATE],">"&EDATE(Charts[[#This Row],[Date]],-12),Sold[DATE],"<="&Charts[[#This Row],[Date]]),#REF!) | R3: =IFERROR(AVERAGEIFS(Sold[SOLD CAP],Sold[FIRM],"<"&0.5,Sold[DATE],">"&EDATE(Charts[[#This Row],[Date]],-12),Sold[DATE],"<="&Charts[[#This Row],[Date]],Sold[FIRM],"<>"&" "),#REF!) | S3: =SUMIFS(Sold[SOLD PRICE],Sold[Type2],"*Private*",Sold[DATE],">"&EDATE(Charts[[#This Row],[Date]],-12),Sold[DATE],"<="&Charts[[#This Row],[Date]]) | T3: =SUMIFS(Sold[SOLD PRICE],Sold[Type2],"*REIT*",Sold[DATE],">"&EDATE(Charts[[#This Row],[Date]],-12),Sold[DATE],"<="&Charts[[#This Row],[Date]]) | U3: =SUMIFS(Sold[SOLD PRICE],Sold[Type2],"*Cross*",Sold[DATE],">"&EDATE(Charts[[#This Row],[Date]],-12),Sold[DATE],"<="&Charts[[#This Row],[Date]]) | V3: =SUMIFS(Sold[SOLD PRICE],Sold[Type2],"*Institutional*",Sold[DATE],">"&EDATE(Charts[[#This Row],[Date]],-12),Sold[DATE],"<="&Charts[[#This Row],[Date]]) | W3: =AVERAGEIFS(Sold[SOLD CAP],Sold[DATE],">"&EDATE(Charts[[#This Row],[Date]],-12),Sold[DATE],"<="&Charts[[#This Row],[Date]],Sold[TYPE],"*Federal*") | X3: =AVERAGEIFS(Sold[SOLD CAP],Sold[DATE],">"&EDATE(Charts[[#This Row],[Date]],-12),Sold[DATE],"<="&Charts[[#This Row],[Date]],Sold[TYPE],"*State*") | Y3: =IFERROR(AVERAGEIFS(Sold[SOLD CAP],Sold[DATE],">"&EDATE(Charts[[#This Row],[Date]],-12),Sold[DATE],"<="&Charts[[#This Row],[Date]],Sold[TYPE],"*Municipal*"),Y8) | Z3: =COUNTIFS(Sold[Type2],"*Private*",Sold[DATE],">"&EDATE(Charts[[#This Row],[Date]],-12),Sold[DATE],"<="&Charts[[#This Row],[Date]]) | AA3: =COUNTIFS(Sold[Type2],"*REIT*",Sold[DATE],">"&EDATE(Charts[[#This Row],[Date]],-12),Sold[DATE],"<="&Charts[[#This Row],[Date]]) | AB3: =COUNTIFS(Sold[Type2],"*Cross*",Sold[DATE],">"&EDATE(Charts[[#This Row],[Date]],-12),Sold[DATE],"<="&Charts[[#This Row],[Date]]) | AC3: =COUNTIFS(Sold[Type2],"*Institutional*",Sold[DATE],">"&EDATE(Charts[[#This Row],[Date]],-12),Sold[DATE],"<="&Charts[[#This Row],[Date]]) | AD3: =AVERAGEIFS(Sold[DOM],Sold[DATE],">"&EDATE(Charts[[#This Row],[Date]],-12),Sold[DATE],"<="&Charts[[#This Row],[Date]]) | AE3: =AVERAGEIFS(Sold[% of Int Ach],Sold[DATE],"<="&C3,Sold[DATE],">"&EDATE(Charts[[#This Row],[Date]],-12)) | AF3: =AVERAGEIFS(Sold[LAST CAP],Sold[DATE],"<="&Charts[[#This Row],[Date]],Sold[DATE],">"&EDATE(Charts[[#This Row],[Date]],-12)) | AG3: =AVERAGEIFS(Sold[BID-ASK SPREAD],Sold[DATE],"<="&Charts[[#This Row],[Date]],Sold[DATE],">"&EDATE(Charts[[#This Row],[Date]],-12)) | AH3: 0.04177 | AI3: =PMT((Charts[[#This Row],[10-Year Treasury Yield]]+0.018)/12,360,-1,0)*12 | AJ3: =PMT((Charts[[#This Row],[10-Year Treasury Yield]]+0.022)/12,360,-1,0)*12 | AK3: =COUNTIFS(Sold[PRICE CHG],"*Yes*",Sold[DATE],">"&EDATE(Charts[[#This Row],[Date]],-12),Sold[DATE],"<="&Charts[[#This Row],[Date]])/COUNTIFS(Sold[DOM],"<>",Sold[DATE],">"&EDATE(Charts[[#This Row],[Date]],-12),Sold[DATE],"<="&Charts[[#This Row],[Date]]) | AL3: =AVERAGEIFS(Sold[LAST CAP],Sold[DATE],">"&EDATE(Charts[[#This Row],[Date]],-12),Sold[DATE],"<="&Charts[[#This Row],[Date]],Sold[FIRM],">="&7.5) | AM3: =COUNTIFS(Sold[PRICE CHG],"*Yes*",Sold[DATE],">"&EDATE(Charts[[#This Row],[Date]],-12),Sold[DATE],"<="&Charts[[#This Row],[Date]],Sold[FIRM],">="&7.5)/COUNTIFS(Sold[DOM],"<>",Sold[DATE],">"&EDATE(Charts[[#This Row],[Date]],-12),Sold[DATE],"<="&Charts[[#This Row],[Date]],Sold[FIRM],">="&7.5) | AN3: =COUNTIFS(Ownership[COM],">"&EDATE(Charts[[#This Row],[Date]],-12),Ownership[COM],"<="&Charts[[#This Row],[Date]],Ownership[Last],"New") | AO3: =(COUNTIFS(Ownership[COM],">"&EDATE(Charts[[#This Row],[Date]],-12),Ownership[COM],"<="&Charts[[#This Row],[Date]],Ownership[Last],"*replacing*"))+(COUNTIFS(Ownership[COM],">"&EDATE(Charts[[#This Row],[Date]],-12),Ownership[COM],"<="&Charts[[#This Row],[Date]],Ownership[Last],"*renew*"))+(COUNTIFS(Ownership[COM],">"&EDATE(Charts[[#This Row],[Date]],-12),Ownership[COM],"<="&Charts[[#This Row],[Date]],Ownership[Last],"*exten*")) | AP3: =(COUNTIFS(Ownership[COM],">"&EDATE(Charts[[#This Row],[Date]],-12),Ownership[COM],"<="&Charts[[#This Row],[Date]],Ownership[Last],"*succeed*"))+(COUNTIFS(Ownership[COM],">"&EDATE(Charts[[#This Row],[Date]],-12),Ownership[COM],"<="&Charts[[#This Row],[Date]],Ownership[Last],"*superse*")) | AQ3: =-COUNTIFS(Ownership[EXP],"<="&Charts[[#This Row],[Date]],Ownership[EXP],">"&EDATE(Charts[[#This Row],[Date]],-12),Ownership[NEW],"#N/A") | AR3: =Charts[[#This Row],[Expired Leases (ttm)]]+COUNTIFS(Ownership[EXP],"<="&Charts[[#This Row],[Date]],Ownership[EXP],">"&EDATE(Charts[[#This Row],[Date]],-12),Ownership[NEW],"#N/A",Ownership[TERMN],"<="&EDATE(Charts[[#This Row],[Date]],-12)) | AS3: =Charts[[#This Row],[First Generation Lease Commencements (ttm)]]+Charts[[#This Row],[Renewed Leases (ttm)]]+Charts[[#This Row],[Succeeding/Superseding Leases (ttm)]]+Charts[[#This Row],[Expired Leases (ttm)]]+Charts[[#This Row],[Terminated Leases (ttm)]] | AT3: =(COUNTIFS(Ownership[EXP],">="&Charts[[#This Row],[Date]],Ownership[COM],"<="&Charts[[#This Row],[Date]],Ownership[NEW],"<>*#N/A*")) | AU3: =COUNTIFS(Ownership[RENEWED],"*Yes*",Ownership[Date],">"&EDATE(Charts[[#This Row],[Date]],-12),Ownership[Date],"<="&Charts[[#This Row],[Date]]) | AV3: =COUNTIFS(Ownership[RENEWED],"*Reduced*",Ownership[Date],">"&EDATE(Charts[[#This Row],[Date]],-12),Ownership[Date],"<="&Charts[[#This Row],[Date]]) | AW3: =COUNTIFS(Ownership[RENEWED],"*No*",Ownership[Date],">"&EDATE(Charts[[#This Row],[Date]],-12),Ownership[Date],"<="&Charts[[#This Row],[Date]]) | AX3: =SUM(Charts[[#This Row],[Leases Extended (ttm)]:[Leases Expired (ttm)]]) | AY3: =Charts[[#This Row],[Total Current Leases (ttm)]]-Charts[[#This Row],[Leases Outside Firm (ttm)]] | AZ3: =COUNTIFS(Ownership[TERMN],"<"&C3,Ownership[EXP],">"&C3) | BA3: =-Charts[[#This Row],[Terminated Leases (ttm)]]/Charts[[#This Row],[Leases Outside Firm (ttm)]] | BB3: =AVERAGEIFS(Ownership[FUTURE/SF],Ownership[FUTURE/SF],"<>"&0,Ownership[EXP],">="&EDATE(Charts[[#This Row],[Date]],-12),Ownership[EXP],"<="&Charts[[#This Row],[Date]]) | BC3: {=PERCENTILE(IF(Ownership[EXP]>EDATE(Charts[[#This Row],[Date]],-12),IF(Ownership[EXP]<=Charts[[#This Row],[Date]],IF(Ownership[CAGR]<>0,Ownership[CAGR]))),0.75)} | BD3: {=PERCENTILE(IF(Ownership[EXP]>EDATE(Charts[[#This Row],[Date]],-12),IF(Ownership[EXP]<=Charts[[#This Row],[Date]],IF(Ownership[CAGR]<>0,Ownership[CAGR]))),0.25)} | BE3: =AVERAGEIFS(Ownership[CAGR],Ownership[CAGR],"<>"&0,Ownership[EXP],">="&EDATE(Charts[[#This Row],[Date]],-12),Ownership[EXP],"<="&Charts[[#This Row],[Date]],Ownership[Term],">="&3) | BF3: =AVERAGEIFS(Ownership[Tenure at Com],Ownership[COM],">"&EDATE(Charts[[#This Row],[Date]],-12),Ownership[COM],"<="&Charts[[#This Row],[Date]]) | BG3: =AVERAGEIFS(Ownership[Term],Ownership[COM],">"&EDATE(Charts[[#This Row],[Date]],-12),Ownership[COM],"<="&Charts[[#This Row],[Date]]) | BH3: =AVERAGEIFS(Ownership['#ofRenewals],Ownership[COM],"<="&Charts[[#This Row],[Date]],Ownership[COM],">"&EDATE(Charts[[#This Row],[Date]],-12)) | BI3: =AVERAGE(AVERAGEIFS(Ownership[GROSS/SF],Ownership[EXP],"<="&Charts[[#This Row],[Date]],Ownership[Term],">="&0),AVERAGEIFS(Sold[GROSS/SF],Sold[EXP],"<="&Charts[[#This Row],[Date]],Sold[TERM],">="&0)) | BJ3: =(Charts[[#This Row],[Avg. Rent]]-Charts[[#This Row],[Expenses PSF (ttm)]])/Charts[[#This Row],[Average Cap Rate (ttm)]] | BK3: =(Charts[[#This Row],[Valuation Index]]-BJ15)/BJ15 | BL3: =AVERAGEIFS(Sold[GROSS/SF],Sold[DATE],"<="&Charts[[#This Row],[Date]],Sold[DATE],">"&EDATE(Charts[[#This Row],[Date]],-12),Sold[GROSS/SF],"<>"&0,Sold[NET/SF],"<>"&0)-AVERAGEIFS(Sold[NET/SF],Sold[DATE],"<="&Charts[[#This Row],[Date]],Sold[DATE],">"&EDATE(Charts[[#This Row],[Date]],-12),Sold[GROSS/SF],"<>"&0,Sold[NET/SF],"<>"&0) | BM3: =(Charts[[#This Row],[Lower Quartile Cap Rate (ttm)]]*0.25)+(Charts[[#This Row],[Average Cap Rate (ttm)]]*0.5)+(Charts[[#This Row],[Upper Quartile Cap Rate (ttm)]]*0.25) | BN3: =(1-((1/Charts[[#This Row],[Cash Return Index]])*0.5)*AVERAGE(Charts[[#This Row],[Low Assumed Loan Constant]:[High Assumed Loan Constant]]))/((1/Charts[[#This Row],[Cash Return Index]])*0.5)
C4: 45808 | D4: =COUNTIFS(Sold[DATE],">"&EDATE(Charts[[#This Row],[Date]],-12),Sold[DATE],"<="&Charts[[#This Row],[Date]]) | E4: =AVERAGEIFS(Sold[SOLD PRICE],Sold[DATE],">"&EDATE(Charts[[#This Row],[Date]],-12),Sold[DATE],"<="&Charts[[#This Row],[Date]]) | F4: =SUMIFS(Sold[SOLD PRICE],Sold[DATE],">"&EDATE(Charts[[#This Row],[Date]],-1),Sold[DATE],"<="&Charts[[#This Row],[Date]]) | G4: =SUMIFS(Sold[SOLD PRICE],Sold[DATE],">"&EDATE(Charts[[#This Row],[Date]],-12),Sold[DATE],"<="&Charts[[#This Row],[Date]]) | H4: =Charts[[#This Row],[Average Deal Size (ttm)]]*Charts[[#This Row],[Transactions (ttm)]] | I4: =(Charts[[#This Row],[Trans. Vol. (ttm)]]-H16)/H16 | J4: {=PERCENTILE(IF(Sold[DATE]>EDATE(Charts[[#This Row],[Date]],-12),IF(Sold[DATE]<=Charts[[#This Row],[Date]],IF(Sold[SOLD CAP]<>"",Sold[SOLD CAP]))),0.75)} | K4: {=PERCENTILE(IF(Sold[DATE]>EDATE(Charts[[#This Row],[Date]],-12),IF(Sold[DATE]<=Charts[[#This Row],[Date]],IF(Sold[SOLD CAP]<>"",Sold[SOLD CAP]))),0.25)} | L4: =AVERAGEIFS(Sold[SOLD CAP],Sold[DATE],">"&EDATE(Charts[[#This Row],[Date]],-12),Sold[DATE],"<="&Charts[[#This Row],[Date]]) | M4: =IFERROR(AVERAGEIFS(Sold[SOLD CAP],Sold[DATE],">"&EDATE(Charts[[#This Row],[Date]],-12),Sold[DATE],"<="&Charts[[#This Row],[Date]],Sold[L. BROKER],"*sjc*",Sold[SOLD CAP],"<=.09"),M9) | N4: =IF(Charts[[#This Row],[Average Cap Rate (ttm)]]>(AVERAGEIFS(Sold[SOLD CAP],Sold[L. BROKER],"<>*",Sold[L. BROKER],"<>*sjc*",Sold[DATE],">"&EDATE(Charts[[#This Row],[Date]],-12),Sold[DATE],"<="&Charts[[#This Row],[Date]])),Charts[[#This Row],[Average Cap Rate (ttm)]],AVERAGEIFS(Sold[SOLD CAP],Sold[L. BROKER],"<>*",Sold[L. BROKER],"<>*sjc*",Sold[DATE],">"&EDATE(Charts[[#This Row],[Date]],-12),Sold[DATE],"<="&Charts[[#This Row],[Date]])) | O4: =IFERROR(AVERAGEIFS(Sold[SOLD CAP],Sold[FIRM],">="&10,Sold[DATE],">"&EDATE(Charts[[#This Row],[Date]],-12),Sold[DATE],"<="&Charts[[#This Row],[Date]]),#REF!) | P4: =IFERROR(AVERAGEIFS(Sold[SOLD CAP],Sold[FIRM],">="&6,Sold[FIRM],"<"&10,Sold[DATE],">"&EDATE(Charts[[#This Row],[Date]],-12),Sold[DATE],"<="&Charts[[#This Row],[Date]]),#REF!) | Q4: =IFERROR(AVERAGEIFS(Sold[SOLD CAP],Sold[FIRM],"<"&6,Sold[DATE],">"&EDATE(Charts[[#This Row],[Date]],-12),Sold[DATE],"<="&Charts[[#This Row],[Date]]),#REF!) | R4: =IFERROR(AVERAGEIFS(Sold[SOLD CAP],Sold[FIRM],"<"&0.5,Sold[DATE],">"&EDATE(Charts[[#This Row],[Date]],-12),Sold[DATE],"<="&Charts[[#This Row],[Date]],Sold[FIRM],"<>"&" "),#REF!) | S4: =SUMIFS(Sold[SOLD PRICE],Sold[Type2],"*Private*",Sold[DATE],">"&EDATE(Charts[[#This Row],[Date]],-12),Sold[DATE],"<="&Charts[[#This Row],[Date]]) | T4: =SUMIFS(Sold[SOLD PRICE],Sold[Type2],"*REIT*",Sold[DATE],">"&EDATE(Charts[[#This Row],[Date]],-12),Sold[DATE],"<="&Charts[[#This Row],[Date]]) | U4: =SUMIFS(Sold[SOLD PRICE],Sold[Type2],"*Cross*",Sold[DATE],">"&EDATE(Charts[[#This Row],[Date]],-12),Sold[DATE],"<="&Charts[[#This Row],[Date]]) | V4: =SUMIFS(Sold[SOLD PRICE],Sold[Type2],"*Institutional*",Sold[DATE],">"&EDATE(Charts[[#This Row],[Date]],-12),Sold[DATE],"<="&Charts[[#This Row],[Date]]) | W4: =AVERAGEIFS(Sold[SOLD CAP],Sold[DATE],">"&EDATE(Charts[[#This Row],[Date]],-12),Sold[DATE],"<="&Charts[[#This Row],[Date]],Sold[TYPE],"*Federal*") | X4: =AVERAGEIFS(Sold[SOLD CAP],Sold[DATE],">"&EDATE(Charts[[#This Row],[Date]],-12),Sold[DATE],"<="&Charts[[#This Row],[Date]],Sold[TYPE],"*State*") | Y4: =IFERROR(AVERAGEIFS(Sold[SOLD CAP],Sold[DATE],">"&EDATE(Charts[[#This Row],[Date]],-12),Sold[DATE],"<="&Charts[[#This Row],[Date]],Sold[TYPE],"*Municipal*"),Y9) | Z4: =COUNTIFS(Sold[Type2],"*Private*",Sold[DATE],">"&EDATE(Charts[[#This Row],[Date]],-12),Sold[DATE],"<="&Charts[[#This Row],[Date]]) | AA4: =COUNTIFS(Sold[Type2],"*REIT*",Sold[DATE],">"&EDATE(Charts[[#This Row],[Date]],-12),Sold[DATE],"<="&Charts[[#This Row],[Date]]) | AB4: =COUNTIFS(Sold[Type2],"*Cross*",Sold[DATE],">"&EDATE(Charts[[#This Row],[Date]],-12),Sold[DATE],"<="&Charts[[#This Row],[Date]]) | AC4: =COUNTIFS(Sold[Type2],"*Institutional*",Sold[DATE],">"&EDATE(Charts[[#This Row],[Date]],-12),Sold[DATE],"<="&Charts[[#This Row],[Date]]) | AD4: =AVERAGEIFS(Sold[DOM],Sold[DATE],">"&EDATE(Charts[[#This Row],[Date]],-12),Sold[DATE],"<="&Charts[[#This Row],[Date]]) | AE4: =AVERAGEIFS(Sold[% of Int Ach],Sold[DATE],"<="&C4,Sold[DATE],">"&EDATE(Charts[[#This Row],[Date]],-12)) | AF4: =AVERAGEIFS(Sold[LAST CAP],Sold[DATE],"<="&Charts[[#This Row],[Date]],Sold[DATE],">"&EDATE(Charts[[#This Row],[Date]],-12)) | AG4: =AVERAGEIFS(Sold[BID-ASK SPREAD],Sold[DATE],"<="&Charts[[#This Row],[Date]],Sold[DATE],">"&EDATE(Charts[[#This Row],[Date]],-12)) | AH4: 0.04177 | AI4: =PMT((Charts[[#This Row],[10-Year Treasury Yield]]+0.018)/12,360,-1,0)*12 | AJ4: =PMT((Charts[[#This Row],[10-Year Treasury Yield]]+0.022)/12,360,-1,0)*12 | AK4: =COUNTIFS(Sold[PRICE CHG],"*Yes*",Sold[DATE],">"&EDATE(Charts[[#This Row],[Date]],-12),Sold[DATE],"<="&Charts[[#This Row],[Date]])/COUNTIFS(Sold[DOM],"<>",Sold[DATE],">"&EDATE(Charts[[#This Row],[Date]],-12),Sold[DATE],"<="&Charts[[#This Row],[Date]]) | AL4: =AVERAGEIFS(Sold[LAST CAP],Sold[DATE],">"&EDATE(Charts[[#This Row],[Date]],-12),Sold[DATE],"<="&Charts[[#This Row],[Date]],Sold[FIRM],">="&7.5) | AM4: =COUNTIFS(Sold[PRICE CHG],"*Yes*",Sold[DATE],">"&EDATE(Charts[[#This Row],[Date]],-12),Sold[DATE],"<="&Charts[[#This Row],[Date]],Sold[FIRM],">="&7.5)/COUNTIFS(Sold[DOM],"<>",Sold[DATE],">"&EDATE(Charts[[#This Row],[Date]],-12),Sold[DATE],"<="&Charts[[#This Row],[Date]],Sold[FIRM],">="&7.5) | AN4: =COUNTIFS(Ownership[COM],">"&EDATE(Charts[[#This Row],[Date]],-12),Ownership[COM],"<="&Charts[[#This Row],[Date]],Ownership[Last],"New") | AO4: =(COUNTIFS(Ownership[COM],">"&EDATE(Charts[[#This Row],[Date]],-12),Ownership[COM],"<="&Charts[[#This Row],[Date]],Ownership[Last],"*replacing*"))+(COUNTIFS(Ownership[COM],">"&EDATE(Charts[[#This Row],[Date]],-12),Ownership[COM],"<="&Charts[[#This Row],[Date]],Ownership[Last],"*renew*"))+(COUNTIFS(Ownership[COM],">"&EDATE(Charts[[#This Row],[Date]],-12),Ownership[COM],"<="&Charts[[#This Row],[Date]],Ownership[Last],"*exten*")) | AP4: =(COUNTIFS(Ownership[COM],">"&EDATE(Charts[[#This Row],[Date]],-12),Ownership[COM],"<="&Charts[[#This Row],[Date]],Ownership[Last],"*succeed*"))+(COUNTIFS(Ownership[COM],">"&EDATE(Charts[[#This Row],[Date]],-12),Ownership[COM],"<="&Charts[[#This Row],[Date]],Ownership[Last],"*superse*")) | AQ4: =-COUNTIFS(Ownership[EXP],"<="&Charts[[#This Row],[Date]],Ownership[EXP],">"&EDATE(Charts[[#This Row],[Date]],-12),Ownership[NEW],"#N/A") | AR4: =Charts[[#This Row],[Expired Leases (ttm)]]+COUNTIFS(Ownership[EXP],"<="&Charts[[#This Row],[Date]],Ownership[EXP],">"&EDATE(Charts[[#This Row],[Date]],-12),Ownership[NEW],"#N/A",Ownership[TERMN],"<="&EDATE(Charts[[#This Row],[Date]],-12)) | AS4: =Charts[[#This Row],[First Generation Lease Commencements (ttm)]]+Charts[[#This Row],[Renewed Leases (ttm)]]+Charts[[#This Row],[Succeeding/Superseding Leases (ttm)]]+Charts[[#This Row],[Expired Leases (ttm)]]+Charts[[#This Row],[Terminated Leases (ttm)]] | AT4: =(COUNTIFS(Ownership[EXP],">="&Charts[[#This Row],[Date]],Ownership[COM],"<="&Charts[[#This Row],[Date]],Ownership[NEW],"<>*#N/A*")) | AU4: =COUNTIFS(Ownership[RENEWED],"*Yes*",Ownership[Date],">"&EDATE(Charts[[#This Row],[Date]],-12),Ownership[Date],"<="&Charts[[#This Row],[Date]]) | AV4: =COUNTIFS(Ownership[RENEWED],"*Reduced*",Ownership[Date],">"&EDATE(Charts[[#This Row],[Date]],-12),Ownership[Date],"<="&Charts[[#This Row],[Date]]) | AW4: =COUNTIFS(Ownership[RENEWED],"*No*",Ownership[Date],">"&EDATE(Charts[[#This Row],[Date]],-12),Ownership[Date],"<="&Charts[[#This Row],[Date]]) | AX4: =SUM(Charts[[#This Row],[Leases Extended (ttm)]:[Leases Expired (ttm)]]) | AY4: =Charts[[#This Row],[Total Current Leases (ttm)]]-Charts[[#This Row],[Leases Outside Firm (ttm)]] | AZ4: =COUNTIFS(Ownership[TERMN],"<"&C4,Ownership[EXP],">"&C4) | BA4: =-Charts[[#This Row],[Terminated Leases (ttm)]]/Charts[[#This Row],[Leases Outside Firm (ttm)]] | BB4: =AVERAGEIFS(Ownership[FUTURE/SF],Ownership[FUTURE/SF],"<>"&0,Ownership[EXP],">="&EDATE(Charts[[#This Row],[Date]],-12),Ownership[EXP],"<="&Charts[[#This Row],[Date]]) | BC4: {=PERCENTILE(IF(Ownership[EXP]>EDATE(Charts[[#This Row],[Date]],-12),IF(Ownership[EXP]<=Charts[[#This Row],[Date]],IF(Ownership[CAGR]<>0,Ownership[CAGR]))),0.75)} | BD4: {=PERCENTILE(IF(Ownership[EXP]>EDATE(Charts[[#This Row],[Date]],-12),IF(Ownership[EXP]<=Charts[[#This Row],[Date]],IF(Ownership[CAGR]<>0,Ownership[CAGR]))),0.25)} | BE4: =AVERAGEIFS(Ownership[CAGR],Ownership[CAGR],"<>"&0,Ownership[EXP],">="&EDATE(Charts[[#This Row],[Date]],-12),Ownership[EXP],"<="&Charts[[#This Row],[Date]],Ownership[Term],">="&3) | BF4: =AVERAGEIFS(Ownership[Tenure at Com],Ownership[COM],">"&EDATE(Charts[[#This Row],[Date]],-12),Ownership[COM],"<="&Charts[[#This Row],[Date]]) | BG4: =AVERAGEIFS(Ownership[Term],Ownership[COM],">"&EDATE(Charts[[#This Row],[Date]],-12),Ownership[COM],"<="&Charts[[#This Row],[Date]]) | BH4: =AVERAGEIFS(Ownership['#ofRenewals],Ownership[COM],"<="&Charts[[#This Row],[Date]],Ownership[COM],">"&EDATE(Charts[[#This Row],[Date]],-12)) | BI4: =AVERAGE(AVERAGEIFS(Ownership[GROSS/SF],Ownership[EXP],"<="&Charts[[#This Row],[Date]],Ownership[Term],">="&0),AVERAGEIFS(Sold[GROSS/SF],Sold[EXP],"<="&Charts[[#This Row],[Date]],Sold[TERM],">="&0)) | BJ4: =(Charts[[#This Row],[Avg. Rent]]-Charts[[#This Row],[Expenses PSF (ttm)]])/Charts[[#This Row],[Average Cap Rate (ttm)]] | BK4: =(Charts[[#This Row],[Valuation Index]]-BJ16)/BJ16 | BL4: =AVERAGEIFS(Sold[GROSS/SF],Sold[DATE],"<="&Charts[[#This Row],[Date]],Sold[DATE],">"&EDATE(Charts[[#This Row],[Date]],-12),Sold[GROSS/SF],"<>"&0,Sold[NET/SF],"<>"&0)-AVERAGEIFS(Sold[NET/SF],Sold[DATE],"<="&Charts[[#This Row],[Date]],Sold[DATE],">"&EDATE(Charts[[#This Row],[Date]],-12),Sold[GROSS/SF],"<>"&0,Sold[NET/SF],"<>"&0) | BM4: =(Charts[[#This Row],[Lower Quartile Cap Rate (ttm)]]*0.25)+(Charts[[#This Row],[Average Cap Rate (ttm)]]*0.5)+(Charts[[#This Row],[Upper Quartile Cap Rate (ttm)]]*0.25) | BN4: =(1-((1/Charts[[#This Row],[Cash Return Index]])*0.5)*AVERAGE(Charts[[#This Row],[Low Assumed Loan Constant]:[High Assumed Loan Constant]]))/((1/Charts[[#This Row],[Cash Return Index]])*0.5)

Sheet SSA Charts
D1: =AVERAGE(SSACharts[Transactions (ttm)])
B2: Quarter | C2: Date | D2: Transactions (ttm) | E2: Average Deal Size (ttm) | F2: Monthly Volume | G2: Transaction Volume (ttm) | H2: Trans. Vol. (ttm) | I2: y-o-y Change (%) | J2: Upper Quartile Cap Rate (ttm) | K2: Lower Quartile Cap Rate (ttm) | L2: Average Cap Rate (ttm) | M2: SJC Average Cap (ttm) | N2: Non-SJC Average Cap (ttm) | O2: 3+ Year Cap (ttm) | P2: 0 to 3 Year Cap (ttm) | Q2: 2.5 to 5 Year Cap (ttm) | R2: Less than 2.5 Year Cap (ttm) | S2: Outside Firm Term (ttm) | T2: Private Volume (ttm) | U2: Public Listed/REIT Volume (ttm) | V2: Cross-Border Volume (ttm) | W2: Institutional Volume (ttm) | X2: Private Count (ttm) | Y2: Public Listed/REIT Count (ttm) | Z2: Cross-Border Count (ttm) | AA2: Institutional Count (ttm) | AB2: DOM | AC2: % of Ask | AD2: Last Ask | AE2: Bid-Ask Spread | AF2: 10-Year Treasury Yield | AG2: Low Assumed Loan Constant | AH2: High Assumed Loan Constant | AI2: Price Change (ttm) | AJ2: 3+ Year Firm Ask (ttm) | AK2: 3+ Year Firm Price Change (ttm) | AL2: First Generation Lease Commencements (ttm) | AM2: Renewed Leases (ttm) | AN2: Succeeding/Superseding Leases (ttm) | AO2: Expired Leases (ttm) | AP2: Terminated Leases (ttm) | AQ2: Net Change (ttm) | AR2: Total Current Leases (ttm) | AS2: Leases Extended (ttm) | AT2: Footprint Reduced (ttm) | AU2: Leases Expired (ttm) | AV2: Leases Up for Renewal (ttm) | AW2: Leases In Firm Term (ttm) | AX2: Leases Outside Firm (ttm) | AY2: Leases Terminated (ttm)
B3: Q4-2022 | C3: 44926 | D3: =COUNTIFS(Sold[DATE],">"&EDATE(SSACharts[[#This Row],[Date]],-12),Sold[DATE],"<="&SSACharts[[#This Row],[Date]],Sold[AGENCY],"*SSA*") | E3: =AVERAGEIFS(Sold[SOLD PRICE],Sold[DATE],">"&EDATE(SSACharts[[#This Row],[Date]],-12),Sold[DATE],"<="&SSACharts[[#This Row],[Date]],Sold[AGENCY],"*ssa*",Sold[SOLD PRICE],"<"&25000000) | F3: =SUMIFS(Sold[SOLD PRICE],Sold[DATE],">"&EDATE(SSACharts[[#This Row],[Date]],-1),Sold[DATE],"<="&SSACharts[[#This Row],[Date]],Sold[AGENCY],"*ssa*") | G3: =SUMIFS(Sold[SOLD PRICE],Sold[DATE],">"&EDATE(SSACharts[[#This Row],[Date]],-12),Sold[DATE],"<="&SSACharts[[#This Row],[Date]],Sold[AGENCY],"*ssa*") | H3: =SSACharts[[#This Row],[Transactions (ttm)]]*SSACharts[[#This Row],[Average Deal Size (ttm)]] | I3: =(SSACharts[[#This Row],[Trans. Vol. (ttm)]]-H14)/H14 | J3: {=PERCENTILE(IF(Sold[DATE]>EDATE(SSACharts[[#This Row],[Date]],-12),IF(Sold[DATE]<=SSACharts[[#This Row],[Date]],IF(Sold[SOLD CAP]<>"",IF(Sold[AGENCY]="ssa",Sold[SOLD CAP])))),0.75)} | K3: {=PERCENTILE(IF(Sold[DATE]>EDATE(SSACharts[[#This Row],[Date]],-12),IF(Sold[DATE]<=SSACharts[[#This Row],[Date]],IF(Sold[SOLD CAP]<>"",IF(Sold[AGENCY]="ssa",Sold[SOLD CAP])))),0.25)} | L3: =AVERAGEIFS(Sold[SOLD CAP],Sold[DATE],">"&EDATE(SSACharts[[#This Row],[Date]],-12),Sold[DATE],"<="&SSACharts[[#This Row],[Date]],Sold[AGENCY],"*ssa*") | M3: =IFERROR(AVERAGE(AVERAGEIFS(Sold[SOLD CAP],Sold[DATE],">"&EDATE(SSACharts[[#This Row],[Date]],-12),Sold[DATE],"<="&SSACharts[[#This Row],[Date]],Sold[L. BROKER],"*sjc*",Sold[AGENCY],"*ssa*"),IFERROR(AVERAGEIFS(Sold[SOLD CAP],Sold[DATE],">"&EDATE(SSACharts[[#This Row],[Date]],-12),Sold[DATE],"<="&SSACharts[[#This Row],[Date]],Sold[P. BROKER],"*sjc*",Sold[AGENCY],"*ssa*"),M2)),M2) | N3: =IFERROR(AVERAGEIFS(Sold[SOLD CAP],Sold[L. BROKER],"<>*sjc*",Sold[L. BROKER],"<>0",Sold[P. BROKER],"<>*sjc*",Sold[DATE],">"&EDATE(SSACharts[[#This Row],[Date]],-12),Sold[DATE],"<="&SSACharts[[#This Row],[Date]],Sold[AGENCY],"*ssa*",Sold[SOLD PRICE],"<="&10000000),N2) | O3: =IFERROR(AVERAGEIFS(Sold[SOLD CAP],Sold[FIRM],">="&3,Sold[DATE],">"&EDATE(SSACharts[[#This Row],[Date]],-12),Sold[DATE],"<="&SSACharts[[#This Row],[Date]],Sold[AGENCY],"*ssa*"),O2) | P3: =IFERROR(AVERAGEIFS(Sold[SOLD CAP],Sold[FIRM],">="&0,Sold[FIRM],"<"&3,Sold[DATE],">"&EDATE(SSACharts[[#This Row],[Date]],-12),Sold[DATE],"<="&SSACharts[[#This Row],[Date]],Sold[AGENCY],"*ssa*"),P2) | Q3: =IFERROR(AVERAGEIFS(Sold[SOLD CAP],Sold[FIRM],">="&2.5,Sold[FIRM],"<"&5,Sold[DATE],">"&EDATE(SSACharts[[#This Row],[Date]],-12),Sold[DATE],"<="&SSACharts[[#This Row],[Date]],Sold[AGENCY],"*ssa*"),Q2) | R3: =IFERROR(AVERAGEIFS(Sold[SOLD CAP],Sold[FIRM],"<"&2.5,Sold[FIRM],">="&0,Sold[DATE],">"&EDATE(SSACharts[[#This Row],[Date]],-12),Sold[DATE],"<="&SSACharts[[#This Row],[Date]],Sold[AGENCY],"*ssa*"),R2) | S3: =IFERROR(AVERAGEIFS(Sold[SOLD CAP],Sold[FIRM],"<"&0,Sold[FIRM],"<>"&" ",Sold[DATE],">"&EDATE(SSACharts[[#This Row],[Date]],-12),Sold[DATE],"<="&SSACharts[[#This Row],[Date]],Sold[AGENCY],"*ssa*"),R2) | AB3: =IFERROR(AVERAGEIFS(Sold[DOM],Sold[DATE],">"&EDATE(SSACharts[[#This Row],[Date]],-12),Sold[DATE],"<="&SSACharts[[#This Row],[Date]],Sold[AGENCY],"*ssa*"),AB2) | AC3: =IFERROR(AVERAGEIFS(Sold[% of Int Ach],Sold[DATE],"<="&C3,Sold[DATE],">"&EDATE(SSACharts[[#This Row],[Date]],-12),Sold[AGENCY],"*ssa*"),AC2) | AD3: =IFERROR(AVERAGEIFS(Sold[LAST CAP],Sold[DATE],"<="&SSACharts[[#This Row],[Date]],Sold[DATE],">"&EDATE(SSACharts[[#This Row],[Date]],-12),Sold[AGENCY],"*ssa*"),AD2) | AE3: =IFERROR(AVERAGEIFS(Sold[BID-ASK SPREAD],Sold[DATE],"<="&SSACharts[[#This Row],[Date]],Sold[DATE],">"&EDATE(SSACharts[[#This Row],[Date]],-12),Sold[AGENCY],"*ssa*"),AE2) | AF3: 0.0353 | AG3: =PMT((SSACharts[[#This Row],[10-Year Treasury Yield]]+0.018)/12,360,-1,0)*12 | AH3: =PMT((SSACharts[[#This Row],[10-Year Treasury Yield]]+0.022)/12,360,-1,0)*12 | AI3: =IFERROR(COUNTIFS(Sold[PRICE CHG],"*Yes*",Sold[DATE],">"&EDATE(SSACharts[[#This Row],[Date]],-12),Sold[DATE],"<="&SSACharts[[#This Row],[Date]],Sold[AGENCY],"*ssa*")/COUNTIFS(Sold[DOM],"<>",Sold[DATE],">"&EDATE(SSACharts[[#This Row],[Date]],-12),Sold[DATE],"<="&SSACharts[[#This Row],[Date]],Sold[AGENCY],"*ssa*"),AI2) | AJ3: =IFERROR(AVERAGEIFS(Sold[LAST CAP],Sold[DATE],">"&EDATE(SSACharts[[#This Row],[Date]],-12),Sold[DATE],"<="&SSACharts[[#This Row],[Date]],Sold[FIRM],">="&3,Sold[AGENCY],"*ssa*"),AJ2) | AK3: =IFERROR(COUNTIFS(Sold[PRICE CHG],"*Yes*",Sold[DATE],">"&EDATE(SSACharts[[#This Row],[Date]],-12),Sold[DATE],"<="&SSACharts[[#This Row],[Date]],Sold[FIRM],">="&3,Sold[AGENCY],"*ssa*")/COUNTIFS(Sold[DOM],"<>",Sold[DATE],">"&EDATE(SSACharts[[#This Row],[Date]],-12),Sold[DATE],"<="&SSACharts[[#This Row],[Date]],Sold[FIRM],">="&3,Sold[AGENCY],"*ssa*"),AK2) | BD3: 5 - GOVT COUNT & DEAL SIZE CHART
C4: 44895 | D4: =COUNTIFS(Sold[DATE],">"&EDATE(SSACharts[[#This Row],[Date]],-12),Sold[DATE],"<="&SSACharts[[#This Row],[Date]],Sold[AGENCY],"*SSA*") | E4: =AVERAGEIFS(Sold[SOLD PRICE],Sold[DATE],">"&EDATE(SSACharts[[#This Row],[Date]],-12),Sold[DATE],"<="&SSACharts[[#This Row],[Date]],Sold[AGENCY],"*ssa*",Sold[SOLD PRICE],"<"&25000000) | F4: =SUMIFS(Sold[SOLD PRICE],Sold[DATE],">"&EDATE(SSACharts[[#This Row],[Date]],-1),Sold[DATE],"<="&SSACharts[[#This Row],[Date]],Sold[AGENCY],"*ssa*") | G4: =SUMIFS(Sold[SOLD PRICE],Sold[DATE],">"&EDATE(SSACharts[[#This Row],[Date]],-12),Sold[DATE],"<="&SSACharts[[#This Row],[Date]],Sold[AGENCY],"*ssa*") | H4: =SSACharts[[#This Row],[Transactions (ttm)]]*SSACharts[[#This Row],[Average Deal Size (ttm)]] | I4: =(SSACharts[[#This Row],[Trans. Vol. (ttm)]]-H15)/H15 | J4: {=PERCENTILE(IF(Sold[DATE]>EDATE(SSACharts[[#This Row],[Date]],-12),IF(Sold[DATE]<=SSACharts[[#This Row],[Date]],IF(Sold[SOLD CAP]<>"",IF(Sold[AGENCY]="ssa",Sold[SOLD CAP])))),0.75)} | K4: {=PERCENTILE(IF(Sold[DATE]>EDATE(SSACharts[[#This Row],[Date]],-12),IF(Sold[DATE]<=SSACharts[[#This Row],[Date]],IF(Sold[SOLD CAP]<>"",IF(Sold[AGENCY]="ssa",Sold[SOLD CAP])))),0.25)} | L4: =AVERAGEIFS(Sold[SOLD CAP],Sold[DATE],">"&EDATE(SSACharts[[#This Row],[Date]],-12),Sold[DATE],"<="&SSACharts[[#This Row],[Date]],Sold[AGENCY],"*ssa*") | M4: =IFERROR(AVERAGE(AVERAGEIFS(Sold[SOLD CAP],Sold[DATE],">"&EDATE(SSACharts[[#This Row],[Date]],-12),Sold[DATE],"<="&SSACharts[[#This Row],[Date]],Sold[L. BROKER],"*sjc*",Sold[AGENCY],"*ssa*"),IFERROR(AVERAGEIFS(Sold[SOLD CAP],Sold[DATE],">"&EDATE(SSACharts[[#This Row],[Date]],-12),Sold[DATE],"<="&SSACharts[[#This Row],[Date]],Sold[P. BROKER],"*sjc*",Sold[AGENCY],"*ssa*"),M3)),M3) | N4: =IFERROR(AVERAGEIFS(Sold[SOLD CAP],Sold[L. BROKER],"<>*sjc*",Sold[L. BROKER],"<>0",Sold[P. BROKER],"<>*sjc*",Sold[DATE],">"&EDATE(SSACharts[[#This Row],[Date]],-12),Sold[DATE],"<="&SSACharts[[#This Row],[Date]],Sold[AGENCY],"*ssa*",Sold[SOLD PRICE],"<="&10000000),N3) | O4: =IFERROR(AVERAGEIFS(Sold[SOLD CAP],Sold[FIRM],">="&3,Sold[DATE],">"&EDATE(SSACharts[[#This Row],[Date]],-12),Sold[DATE],"<="&SSACharts[[#This Row],[Date]],Sold[AGENCY],"*ssa*"),O3) | P4: =IFERROR(AVERAGEIFS(Sold[SOLD CAP],Sold[FIRM],">="&0,Sold[FIRM],"<"&3,Sold[DATE],">"&EDATE(SSACharts[[#This Row],[Date]],-12),Sold[DATE],"<="&SSACharts[[#This Row],[Date]],Sold[AGENCY],"*ssa*"),P3) | Q4: =IFERROR(AVERAGEIFS(Sold[SOLD CAP],Sold[FIRM],">="&2.5,Sold[FIRM],"<"&5,Sold[DATE],">"&EDATE(SSACharts[[#This Row],[Date]],-12),Sold[DATE],"<="&SSACharts[[#This Row],[Date]],Sold[AGENCY],"*ssa*"),Q3) | R4: =IFERROR(AVERAGEIFS(Sold[SOLD CAP],Sold[FIRM],"<"&2.5,Sold[FIRM],">="&0,Sold[DATE],">"&EDATE(SSACharts[[#This Row],[Date]],-12),Sold[DATE],"<="&SSACharts[[#This Row],[Date]],Sold[AGENCY],"*ssa*"),R3) | S4: =IFERROR(AVERAGEIFS(Sold[SOLD CAP],Sold[FIRM],"<"&0,Sold[FIRM],"<>"&" ",Sold[DATE],">"&EDATE(SSACharts[[#This Row],[Date]],-12),Sold[DATE],"<="&SSACharts[[#This Row],[Date]],Sold[AGENCY],"*ssa*"),R3) | AB4: =IFERROR(AVERAGEIFS(Sold[DOM],Sold[DATE],">"&EDATE(SSACharts[[#This Row],[Date]],-12),Sold[DATE],"<="&SSACharts[[#This Row],[Date]],Sold[AGENCY],"*ssa*"),AB3) | AC4: =IFERROR(AVERAGEIFS(Sold[% of Int Ach],Sold[DATE],"<="&C4,Sold[DATE],">"&EDATE(SSACharts[[#This Row],[Date]],-12),Sold[AGENCY],"*ssa*"),AC3) | AD4: =IFERROR(AVERAGEIFS(Sold[LAST CAP],Sold[DATE],"<="&SSACharts[[#This Row],[Date]],Sold[DATE],">"&EDATE(SSACharts[[#This Row],[Date]],-12),Sold[AGENCY],"*ssa*"),AD3) | AE4: =IFERROR(AVERAGEIFS(Sold[BID-ASK SPREAD],Sold[DATE],"<="&SSACharts[[#This Row],[Date]],Sold[DATE],">"&EDATE(SSACharts[[#This Row],[Date]],-12),Sold[AGENCY],"*ssa*"),AE3) | AF4: 0.0387 | AG4: =PMT((SSACharts[[#This Row],[10-Year Treasury Yield]]+0.018)/12,360,-1,0)*12 | AH4: =PMT((SSACharts[[#This Row],[10-Year Treasury Yield]]+0.022)/12,360,-1,0)*12 | AI4: =IFERROR(COUNTIFS(Sold[PRICE CHG],"*Yes*",Sold[DATE],">"&EDATE(SSACharts[[#This Row],[Date]],-12),Sold[DATE],"<="&SSACharts[[#This Row],[Date]],Sold[AGENCY],"*ssa*")/COUNTIFS(Sold[DOM],"<>",Sold[DATE],">"&EDATE(SSACharts[[#This Row],[Date]],-12),Sold[DATE],"<="&SSACharts[[#This Row],[Date]],Sold[AGENCY],"*ssa*"),AI3) | AJ4: =IFERROR(AVERAGEIFS(Sold[LAST CAP],Sold[DATE],">"&EDATE(SSACharts[[#This Row],[Date]],-12),Sold[DATE],"<="&SSACharts[[#This Row],[Date]],Sold[FIRM],">="&3,Sold[AGENCY],"*ssa*"),AJ3) | AK4: =IFERROR(COUNTIFS(Sold[PRICE CHG],"*Yes*",Sold[DATE],">"&EDATE(SSACharts[[#This Row],[Date]],-12),Sold[DATE],"<="&SSACharts[[#This Row],[Date]],Sold[FIRM],">="&3,Sold[AGENCY],"*ssa*")/COUNTIFS(Sold[DOM],"<>",Sold[DATE],">"&EDATE(SSACharts[[#This Row],[Date]],-12),Sold[DATE],"<="&SSACharts[[#This Row],[Date]],Sold[FIRM],">="&3,Sold[AGENCY],"*ssa*"),AK3)

Sheet Rent Survey
G2: =SUM(F4:F36)/SUM(D4:D36) | H2: =SUM(C4:C36)/SUM(F4:F36)
B3: Year Built | C3: Sum of Rent | D3: Count of Rent | E3: Average Rents | F3: Sum of RBA | G3: Average RBA | H3: Average RPSF | I3: Upper Quartile Rent | J3: Lower Quartile Rent | K3: Median Rent PSF
B4: 2024 | C4: =SUMIFS(Sold[GROSS],Sold[BUILT],B4,Sold[GOV OCCP],">="&0.5)+SUMIFS(Ownership[GROSS],Ownership[BUILT],B4,Ownership[OCCP],">="&50) | D4: =COUNTIFS(Sold[GROSS],">"&0,Sold[BUILT],B4,Sold[GOV OCCP],">="&0.5)+COUNTIFS(Ownership[GROSS],">"&0,Ownership[BUILT],B4,Ownership[OCCP],">="&50) | E4: =C4/D4 | F4: =SUMIFS(Sold[RBA],Sold[BUILT],B4,Sold[GROSS],">"&0,Sold[GOV OCCP],">="&0.5)+SUMIFS(Ownership[SF LEASED],Ownership[BUILT],B4,Ownership[GROSS],">"&0,Ownership[OCCP],">="&50) | G4: =F4/D4 | H4: =C4/F4 | I4: {=PERCENTILE(IF(Sold[BUILT]=B4,Sold[GROSS/SF]),0.75)} | J4: {=PERCENTILE(IF(Sold[BUILT]=B4,Sold[GROSS/SF]),0.25)} | K4: {=MEDIAN(IF(Sold[BUILT]=B4,Sold[GROSS/SF]))} | M4: 15 - Rent by Year Built
B5: 2023 | C5: =SUMIFS(Sold[GROSS],Sold[BUILT],B5,Sold[GOV OCCP],">="&0.5)+SUMIFS(Ownership[GROSS],Ownership[BUILT],B5,Ownership[OCCP],">="&50) | D5: =COUNTIFS(Sold[GROSS],">"&0,Sold[BUILT],B5,Sold[GOV OCCP],">="&0.5)+COUNTIFS(Ownership[GROSS],">"&0,Ownership[BUILT],B5,Ownership[OCCP],">="&50) | E5: =C5/D5 | F5: =SUMIFS(Sold[RBA],Sold[BUILT],B5,Sold[GROSS],">"&0,Sold[GOV OCCP],">="&0.5)+SUMIFS(Ownership[SF LEASED],Ownership[BUILT],B5,Ownership[GROSS],">"&0,Ownership[OCCP],">="&50) | G5: =F5/D5 | H5: =C5/F5 | I5: {=PERCENTILE(IF(Sold[BUILT]=B5,Sold[GROSS/SF]),0.75)} | J5: {=PERCENTILE(IF(Sold[BUILT]=B5,Sold[GROSS/SF]),0.25)} | K5: {=MEDIAN(IF(Sold[BUILT]=B5,Sold[GROSS/SF]))}
B6: 2022 | C6: =SUMIFS(Sold[GROSS],Sold[BUILT],B6,Sold[GOV OCCP],">="&0.5)+SUMIFS(Ownership[GROSS],Ownership[BUILT],B6,Ownership[OCCP],">="&50) | D6: =COUNTIFS(Sold[GROSS],">"&0,Sold[BUILT],B6,Sold[GOV OCCP],">="&0.5)+COUNTIFS(Ownership[GROSS],">"&0,Ownership[BUILT],B6,Ownership[OCCP],">="&50) | E6: =C6/D6 | F6: =SUMIFS(Sold[RBA],Sold[BUILT],B6,Sold[GROSS],">"&0,Sold[GOV OCCP],">="&0.5)+SUMIFS(Ownership[SF LEASED],Ownership[BUILT],B6,Ownership[GROSS],">"&0,Ownership[OCCP],">="&50) | G6: =F6/D6 | H6: =C6/F6 | I6: {=PERCENTILE(IF(Sold[BUILT]=B6,Sold[GROSS/SF]),0.75)} | J6: {=PERCENTILE(IF(Sold[BUILT]=B6,Sold[GROSS/SF]),0.25)} | K6: {=MEDIAN(IF(Sold[BUILT]=B6,Sold[GROSS/SF]))}
B7: 2021 | C7: =SUMIFS(Sold[GROSS],Sold[BUILT],B7,Sold[GOV OCCP],">="&0.5)+SUMIFS(Ownership[GROSS],Ownership[BUILT],B7,Ownership[OCCP],">="&50) | D7: =COUNTIFS(Sold[GROSS],">"&0,Sold[BUILT],B7,Sold[GOV OCCP],">="&0.5)+COUNTIFS(Ownership[GROSS],">"&0,Ownership[BUILT],B7,Ownership[OCCP],">="&50) | E7: =C7/D7 | F7: =SUMIFS(Sold[RBA],Sold[BUILT],B7,Sold[GROSS],">"&0,Sold[GOV OCCP],">="&0.5)+SUMIFS(Ownership[SF LEASED],Ownership[BUILT],B7,Ownership[GROSS],">"&0,Ownership[OCCP],">="&50) | G7: =F7/D7 | H7: =C7/F7 | I7: {=PERCENTILE(IF(Sold[BUILT]=B7,Sold[GROSS/SF]),0.75)} | J7: {=PERCENTILE(IF(Sold[BUILT]=B7,Sold[GROSS/SF]),0.25)} | K7: {=MEDIAN(IF(Sold[BUILT]=B7,Sold[GROSS/SF]))}
B8: 2020 | C8: =SUMIFS(Sold[GROSS],Sold[BUILT],B8,Sold[GOV OCCP],">="&0.5)+SUMIFS(Ownership[GROSS],Ownership[BUILT],B8,Ownership[OCCP],">="&50) | D8: =COUNTIFS(Sold[GROSS],">"&0,Sold[BUILT],B8,Sold[GOV OCCP],">="&0.5)+COUNTIFS(Ownership[GROSS],">"&0,Ownership[BUILT],B8,Ownership[OCCP],">="&50) | E8: =C8/D8 | F8: =SUMIFS(Sold[RBA],Sold[BUILT],B8,Sold[GROSS],">"&0,Sold[GOV OCCP],">="&0.5)+SUMIFS(Ownership[SF LEASED],Ownership[BUILT],B8,Ownership[GROSS],">"&0,Ownership[OCCP],">="&50) | G8: =F8/D8 | H8: =C8/F8 | I8: {=PERCENTILE(IF(Sold[BUILT]=B8,Sold[GROSS/SF]),0.75)} | J8: {=PERCENTILE(IF(Sold[BUILT]=B8,Sold[GROSS/SF]),0.25)} | K8: {=MEDIAN(IF(Sold[BUILT]=B8,Sold[GROSS/SF]))}
B9: 2019 | C9: =SUMIFS(Sold[GROSS],Sold[BUILT],B9,Sold[GOV OCCP],">="&0.5)+SUMIFS(Ownership[GROSS],Ownership[BUILT],B9,Ownership[OCCP],">="&50) | D9: =COUNTIFS(Sold[GROSS],">"&0,Sold[BUILT],B9,Sold[GOV OCCP],">="&0.5)+COUNTIFS(Ownership[GROSS],">"&0,Ownership[BUILT],B9,Ownership[OCCP],">="&50) | E9: =C9/D9 | F9: =SUMIFS(Sold[RBA],Sold[BUILT],B9,Sold[GROSS],">"&0,Sold[GOV OCCP],">="&0.5)+SUMIFS(Ownership[SF LEASED],Ownership[BUILT],B9,Ownership[GROSS],">"&0,Ownership[OCCP],">="&50) | G9: =F9/D9 | H9: =C9/F9 | I9: {=PERCENTILE(IF(Sold[BUILT]=B9,Sold[GROSS/SF]),0.75)} | J9: {=PERCENTILE(IF(Sold[BUILT]=B9,Sold[GROSS/SF]),0.25)} | K9: {=MEDIAN(IF(Sold[BUILT]=B9,Sold[GROSS/SF]))}
B10: 2018 | C10: =SUMIFS(Sold[GROSS],Sold[BUILT],B10,Sold[GOV OCCP],">="&0.5)+SUMIFS(Ownership[GROSS],Ownership[BUILT],B10,Ownership[OCCP],">="&50) | D10: =COUNTIFS(Sold[GROSS],">"&0,Sold[BUILT],B10,Sold[GOV OCCP],">="&0.5)+COUNTIFS(Ownership[GROSS],">"&0,Ownership[BUILT],B10,Ownership[OCCP],">="&50) | E10: =C10/D10 | F10: =SUMIFS(Sold[RBA],Sold[BUILT],B10,Sold[GROSS],">"&0,Sold[GOV OCCP],">="&0.5)+SUMIFS(Ownership[SF LEASED],Ownership[BUILT],B10,Ownership[GROSS],">"&0,Ownership[OCCP],">="&50) | G10: =F10/D10 | H10: =C10/F10 | I10: {=PERCENTILE(IF(Sold[BUILT]=B10,Sold[GROSS/SF]),0.75)} | J10: {=PERCENTILE(IF(Sold[BUILT]=B10,Sold[GROSS/SF]),0.25)} | K10: {=MEDIAN(IF(Sold[BUILT]=B10,Sold[GROSS/SF]))}
B11: 2017 | C11: =SUMIFS(Sold[GROSS],Sold[BUILT],B11,Sold[GOV OCCP],">="&0.5)+SUMIFS(Ownership[GROSS],Ownership[BUILT],B11,Ownership[OCCP],">="&50) | D11: =COUNTIFS(Sold[GROSS],">"&0,Sold[BUILT],B11,Sold[GOV OCCP],">="&0.5)+COUNTIFS(Ownership[GROSS],">"&0,Ownership[BUILT],B11,Ownership[OCCP],">="&50) | E11: =C11/D11 | F11: =SUMIFS(Sold[RBA],Sold[BUILT],B11,Sold[GROSS],">"&0,Sold[GOV OCCP],">="&0.5)+SUMIFS(Ownership[SF LEASED],Ownership[BUILT],B11,Ownership[GROSS],">"&0,Ownership[OCCP],">="&50) | G11: =F11/D11 | H11: =C11/F11 | I11: {=PERCENTILE(IF(Sold[BUILT]=B11,Sold[GROSS/SF]),0.75)} | J11: {=PERCENTILE(IF(Sold[BUILT]=B11,Sold[GROSS/SF]),0.25)} | K11: {=MEDIAN(IF(Sold[BUILT]=B11,Sold[GROSS/SF]))}
B12: 2016 | C12: =SUMIFS(Sold[GROSS],Sold[BUILT],B12,Sold[GOV OCCP],">="&0.5)+SUMIFS(Ownership[GROSS],Ownership[BUILT],B12,Ownership[OCCP],">="&50) | D12: =COUNTIFS(Sold[GROSS],">"&0,Sold[BUILT],B12,Sold[GOV OCCP],">="&0.5)+COUNTIFS(Ownership[GROSS],">"&0,Ownership[BUILT],B12,Ownership[OCCP],">="&50) | E12: =C12/D12 | F12: =SUMIFS(Sold[RBA],Sold[BUILT],B12,Sold[GROSS],">"&0,Sold[GOV OCCP],">="&0.5)+SUMIFS(Ownership[SF LEASED],Ownership[BUILT],B12,Ownership[GROSS],">"&0,Ownership[OCCP],">="&50) | G12: =F12/D12 | H12: =C12/F12 | I12: {=PERCENTILE(IF(Sold[BUILT]=B12,Sold[GROSS/SF]),0.75)} | J12: {=PERCENTILE(IF(Sold[BUILT]=B12,Sold[GROSS/SF]),0.25)} | K12: {=MEDIAN(IF(Sold[BUILT]=B12,Sold[GROSS/SF]))}
B13: 2015 | C13: =SUMIFS(Sold[GROSS],Sold[BUILT],B13,Sold[GOV OCCP],">="&0.5)+SUMIFS(Ownership[GROSS],Ownership[BUILT],B13,Ownership[OCCP],">="&50) | D13: =COUNTIFS(Sold[GROSS],">"&0,Sold[BUILT],B13,Sold[GOV OCCP],">="&0.5)+COUNTIFS(Ownership[GROSS],">"&0,Ownership[BUILT],B13,Ownership[OCCP],">="&50) | E13: =C13/D13 | F13: =SUMIFS(Sold[RBA],Sold[BUILT],B13,Sold[GROSS],">"&0,Sold[GOV OCCP],">="&0.5)+SUMIFS(Ownership[SF LEASED],Ownership[BUILT],B13,Ownership[GROSS],">"&0,Ownership[OCCP],">="&50) | G13: =F13/D13 | H13: =C13/F13 | I13: {=PERCENTILE(IF(Sold[BUILT]=B13,Sold[GROSS/SF]),0.75)} | J13: {=PERCENTILE(IF(Sold[BUILT]=B13,Sold[GROSS/SF]),0.25)} | K13: {=MEDIAN(IF(Sold[BUILT]=B13,Sold[GROSS/SF]))}
B14: 2014 | C14: =SUMIFS(Sold[GROSS],Sold[BUILT],B14,Sold[GOV OCCP],">="&0.5)+SUMIFS(Ownership[GROSS],Ownership[BUILT],B14,Ownership[OCCP],">="&50) | D14: =COUNTIFS(Sold[GROSS],">"&0,Sold[BUILT],B14,Sold[GOV OCCP],">="&0.5)+COUNTIFS(Ownership[GROSS],">"&0,Ownership[BUILT],B14,Ownership[OCCP],">="&50) | E14: =C14/D14 | F14: =SUMIFS(Sold[RBA],Sold[BUILT],B14,Sold[GROSS],">"&0,Sold[GOV OCCP],">="&0.5)+SUMIFS(Ownership[SF LEASED],Ownership[BUILT],B14,Ownership[GROSS],">"&0,Ownership[OCCP],">="&50) | G14: =F14/D14 | H14: =C14/F14 | I14: {=PERCENTILE(IF(Sold[BUILT]=B14,Sold[GROSS/SF]),0.75)} | J14: {=PERCENTILE(IF(Sold[BUILT]=B14,Sold[GROSS/SF]),0.25)} | K14: {=MEDIAN(IF(Sold[BUILT]=B14,Sold[GROSS/SF]))}
B15: 2013 | C15: =SUMIFS(Sold[GROSS],Sold[BUILT],B15,Sold[GOV OCCP],">="&0.5)+SUMIFS(Ownership[GROSS],Ownership[BUILT],B15,Ownership[OCCP],">="&50) | D15: =COUNTIFS(Sold[GROSS],">"&0,Sold[BUILT],B15,Sold[GOV OCCP],">="&0.5)+COUNTIFS(Ownership[GROSS],">"&0,Ownership[BUILT],B15,Ownership[OCCP],">="&50) | E15: =C15/D15 | F15: =SUMIFS(Sold[RBA],Sold[BUILT],B15,Sold[GROSS],">"&0,Sold[GOV OCCP],">="&0.5)+SUMIFS(Ownership[SF LEASED],Ownership[BUILT],B15,Ownership[GROSS],">"&0,Ownership[OCCP],">="&50) | G15: =F15/D15 | H15: =C15/F15 | I15: {=PERCENTILE(IF(Sold[BUILT]=B15,Sold[GROSS/SF]),0.75)} | J15: {=PERCENTILE(IF(Sold[BUILT]=B15,Sold[GROSS/SF]),0.25)} | K15: {=MEDIAN(IF(Sold[BUILT]=B15,Sold[GROSS/SF]))}
B16: 2012 | C16: =SUMIFS(Sold[GROSS],Sold[BUILT],B16,Sold[GOV OCCP],">="&0.5)+SUMIFS(Ownership[GROSS],Ownership[BUILT],B16,Ownership[OCCP],">="&50) | D16: =COUNTIFS(Sold[GROSS],">"&0,Sold[BUILT],B16,Sold[GOV OCCP],">="&0.5)+COUNTIFS(Ownership[GROSS],">"&0,Ownership[BUILT],B16,Ownership[OCCP],">="&50) | E16: =C16/D16 | F16: =SUMIFS(Sold[RBA],Sold[BUILT],B16,Sold[GROSS],">"&0,Sold[GOV OCCP],">="&0.5)+SUMIFS(Ownership[SF LEASED],Ownership[BUILT],B16,Ownership[GROSS],">"&0,Ownership[OCCP],">="&50) | G16: =F16/D16 | H16: =C16/F16 | I16: {=PERCENTILE(IF(Sold[BUILT]=B16,Sold[GROSS/SF]),0.75)} | J16: {=PERCENTILE(IF(Sold[BUILT]=B16,Sold[GROSS/SF]),0.25)} | K16: {=MEDIAN(IF(Sold[BUILT]=B16,Sold[GROSS/SF]))}
... B36: 1992 | C36: =SUMIFS(Sold[GROSS],Sold[BUILT],B36,Sold[GOV OCCP],">="&0.5)+SUMIFS(Ownership[GROSS],Ownership[BUILT],B36,Ownership[OCCP],">="&50) | D36: =COUNTIFS(Sold[GROSS],">"&0,Sold[BUILT],B36,Sold[GOV OCCP],">="&0.5)+COUNTIFS(Ownership[GROSS],">"&0,Ownership[BUILT],B36,Ownership[OCCP],">="&50) | E36: =C36/D36 | F36: =SUMIFS(Sold[RBA],Sold[BUILT],B36,Sold[GROSS],">"&0,Sold[GOV OCCP],">="&0.5)+SUMIFS(Ownership[SF LEASED],Ownership[BUILT],B36,Ownership[GROSS],">"&0,Ownership[OCCP],">="&50) | G36: =F36/D36 | H36: =C36/F36 | I36: {=PERCENTILE(IF(Sold[BUILT]=B36,Sold[GROSS/SF]),0.75)} | J36: {=PERCENTILE(IF(Sold[BUILT]=B36,Sold[GROSS/SF]),0.25)} | K36: {=MEDIAN(IF(Sold[BUILT]=B36,Sold[GROSS/SF]))}
B38: State | C38: Sum of Rent | D38: Count of Rent | E38: Average Rents | F38: Sum of RBA | G38: Average RBA | H38: Average RPSF | I38: Upper Quartile Rent | J38: Lower Quartile Rent | K38: Median Rent PSF
B39: AL | C39: =SUMIFS(Sold[GROSS],Sold[STATE],B39,Sold[GOV OCCP],">="&0.5)+SUMIFS(Ownership[GROSS],Ownership[STATE],B39,Ownership[OCCP],">="&50) | D39: =COUNTIFS(Sold[GROSS],">"&0,Sold[STATE],B39,Sold[GOV OCCP],">="&0.5)+COUNTIFS(Ownership[GROSS],">"&0,Ownership[STATE],B39,Ownership[OCCP],">="&50) | E39: =C39/D39 | F39: =SUMIFS(Sold[RBA],Sold[STATE],B39,Sold[GROSS],">"&0,Sold[GOV OCCP],">="&0.5)+SUMIFS(Ownership[SF LEASED],Ownership[STATE],B39,Ownership[GROSS],">"&0,Ownership[OCCP],">="&50) | G39: =F39/D39 | H39: =C39/F39 | I39: {=PERCENTILE(IF(Ownership[STATE]=B39,Ownership[GROSS/SF]),0.75)} | J39: {=PERCENTILE(IF(Ownership[STATE]=B39,Ownership[GROSS/SF]),0.25)} | K39: {=MEDIAN(IF(Ownership[STATE]=B39,Ownership[GROSS/SF]))}
B40: AK | C40: =SUMIFS(Sold[GROSS],Sold[STATE],B40,Sold[GOV OCCP],">="&0.5)+SUMIFS(Ownership[GROSS],Ownership[STATE],B40,Ownership[OCCP],">="&50) | D40: =COUNTIFS(Sold[GROSS],">"&0,Sold[STATE],B40,Sold[GOV OCCP],">="&0.5)+COUNTIFS(Ownership[GROSS],">"&0,Ownership[STATE],B40,Ownership[OCCP],">="&50) | E40: =C40/D40 | F40: =SUMIFS(Sold[RBA],Sold[STATE],B40,Sold[GROSS],">"&0,Sold[GOV OCCP],">="&0.5)+SUMIFS(Ownership[SF LEASED],Ownership[STATE],B40,Ownership[GROSS],">"&0,Ownership[OCCP],">="&50) | G40: =F40/D40 | H40: =C40/F40 | I40: {=PERCENTILE(IF(Ownership[STATE]=B40,Ownership[GROSS/SF]),0.75)} | J40: {=PERCENTILE(IF(Ownership[STATE]=B40,Ownership[GROSS/SF]),0.25)} | K40: {=MEDIAN(IF(Ownership[STATE]=B40,Ownership[GROSS/SF]))}
B41: AZ | C41: =SUMIFS(Sold[GROSS],Sold[STATE],B41,Sold[GOV OCCP],">="&0.5)+SUMIFS(Ownership[GROSS],Ownership[STATE],B41,Ownership[OCCP],">="&50) | D41: =COUNTIFS(Sold[GROSS],">"&0,Sold[STATE],B41,Sold[GOV OCCP],">="&0.5)+COUNTIFS(Ownership[GROSS],">"&0,Ownership[STATE],B41,Ownership[OCCP],">="&50) | E41: =C41/D41 | F41: =SUMIFS(Sold[RBA],Sold[STATE],B41,Sold[GROSS],">"&0,Sold[GOV OCCP],">="&0.5)+SUMIFS(Ownership[SF LEASED],Ownership[STATE],B41,Ownership[GROSS],">"&0,Ownership[OCCP],">="&50) | G41: =F41/D41 | H41: =C41/F41 | I41: {=PERCENTILE(IF(Ownership[STATE]=B41,Ownership[GROSS/SF]),0.75)} | J41: {=PERCENTILE(IF(Ownership[STATE]=B41,Ownership[GROSS/SF]),0.25)} | K41: {=MEDIAN(IF(Ownership[STATE]=B41,Ownership[GROSS/SF]))}
B42: AR | C42: =SUMIFS(Sold[GROSS],Sold[STATE],B42,Sold[GOV OCCP],">="&0.5)+SUMIFS(Ownership[GROSS],Ownership[STATE],B42,Ownership[OCCP],">="&50) | D42: =COUNTIFS(Sold[GROSS],">"&0,Sold[STATE],B42,Sold[GOV OCCP],">="&0.5)+COUNTIFS(Ownership[GROSS],">"&0,Ownership[STATE],B42,Ownership[OCCP],">="&50) | E42: =C42/D42 | F42: =SUMIFS(Sold[RBA],Sold[STATE],B42,Sold[GROSS],">"&0,Sold[GOV OCCP],">="&0.5)+SUMIFS(Ownership[SF LEASED],Ownership[STATE],B42,Ownership[GROSS],">"&0,Ownership[OCCP],">="&50) | G42: =F42/D42 | H42: =C42/F42 | I42: {=PERCENTILE(IF(Ownership[STATE]=B42,Ownership[GROSS/SF]),0.75)} | J42: {=PERCENTILE(IF(Ownership[STATE]=B42,Ownership[GROSS/SF]),0.25)} | K42: {=MEDIAN(IF(Ownership[STATE]=B42,Ownership[GROSS/SF]))} | M42: 18 - Rent Heat Map
B43: CA | C43: =SUMIFS(Sold[GROSS],Sold[STATE],B43,Sold[GOV OCCP],">="&0.5)+SUMIFS(Ownership[GROSS],Ownership[STATE],B43,Ownership[OCCP],">="&50) | D43: =COUNTIFS(Sold[GROSS],">"&0,Sold[STATE],B43,Sold[GOV OCCP],">="&0.5)+COUNTIFS(Ownership[GROSS],">"&0,Ownership[STATE],B43,Ownership[OCCP],">="&50) | E43: =C43/D43 | F43: =SUMIFS(Sold[RBA],Sold[STATE],B43,Sold[GROSS],">"&0,Sold[GOV OCCP],">="&0.5)+SUMIFS(Ownership[SF LEASED],Ownership[STATE],B43,Ownership[GROSS],">"&0,Ownership[OCCP],">="&50) | G43: =F43/D43 | H43: =C43/F43 | I43: {=PERCENTILE(IF(Ownership[STATE]=B43,Ownership[GROSS/SF]),0.75)} | J43: {=PERCENTILE(IF(Ownership[STATE]=B43,Ownership[GROSS/SF]),0.25)} | K43: {=MEDIAN(IF(Ownership[STATE]=B43,Ownership[GROSS/SF]))}
B44: CO | C44: =SUMIFS(Sold[GROSS],Sold[STATE],B44,Sold[GOV OCCP],">="&0.5)+SUMIFS(Ownership[GROSS],Ownership[STATE],B44,Ownership[OCCP],">="&50) | D44: =COUNTIFS(Sold[GROSS],">"&0,Sold[STATE],B44,Sold[GOV OCCP],">="&0.5)+COUNTIFS(Ownership[GROSS],">"&0,Ownership[STATE],B44,Ownership[OCCP],">="&50) | E44: =C44/D44 | F44: =SUMIFS(Sold[RBA],Sold[STATE],B44,Sold[GROSS],">"&0,Sold[GOV OCCP],">="&0.5)+SUMIFS(Ownership[SF LEASED],Ownership[STATE],B44,Ownership[GROSS],">"&0,Ownership[OCCP],">="&50) | G44: =F44/D44 | H44: =C44/F44 | I44: {=PERCENTILE(IF(Ownership[STATE]=B44,Ownership[GROSS/SF]),0.75)} | J44: {=PERCENTILE(IF(Ownership[STATE]=B44,Ownership[GROSS/SF]),0.25)} | K44: {=MEDIAN(IF(Ownership[STATE]=B44,Ownership[GROSS/SF]))}
B45: CT | C45: =SUMIFS(Sold[GROSS],Sold[STATE],B45,Sold[GOV OCCP],">="&0.5)+SUMIFS(Ownership[GROSS],Ownership[STATE],B45,Ownership[OCCP],">="&50) | D45: =COUNTIFS(Sold[GROSS],">"&0,Sold[STATE],B45,Sold[GOV OCCP],">="&0.5)+COUNTIFS(Ownership[GROSS],">"&0,Ownership[STATE],B45,Ownership[OCCP],">="&50) | E45: =C45/D45 | F45: =SUMIFS(Sold[RBA],Sold[STATE],B45,Sold[GROSS],">"&0,Sold[GOV OCCP],">="&0.5)+SUMIFS(Ownership[SF LEASED],Ownership[STATE],B45,Ownership[GROSS],">"&0,Ownership[OCCP],">="&50) | G45: =F45/D45 | H45: =C45/F45 | I45: {=PERCENTILE(IF(Ownership[STATE]=B45,Ownership[GROSS/SF]),0.75)} | J45: {=PERCENTILE(IF(Ownership[STATE]=B45,Ownership[GROSS/SF]),0.25)} | K45: {=MEDIAN(IF(Ownership[STATE]=B45,Ownership[GROSS/SF]))}
B46: DE | C46: =SUMIFS(Sold[GROSS],Sold[STATE],B46,Sold[GOV OCCP],">="&0.5)+SUMIFS(Ownership[GROSS],Ownership[STATE],B46,Ownership[OCCP],">="&50) | D46: =COUNTIFS(Sold[GROSS],">"&0,Sold[STATE],B46,Sold[GOV OCCP],">="&0.5)+COUNTIFS(Ownership[GROSS],">"&0,Ownership[STATE],B46,Ownership[OCCP],">="&50) | E46: =C46/D46 | F46: =SUMIFS(Sold[RBA],Sold[STATE],B46,Sold[GROSS],">"&0,Sold[GOV OCCP],">="&0.5)+SUMIFS(Ownership[SF LEASED],Ownership[STATE],B46,Ownership[GROSS],">"&0,Ownership[OCCP],">="&50) | G46: =F46/D46 | H46: =C46/F46 | I46: {=PERCENTILE(IF(Ownership[STATE]=B46,Ownership[GROSS/SF]),0.75)} | J46: {=PERCENTILE(IF(Ownership[STATE]=B46,Ownership[GROSS/SF]),0.25)} | K46: {=MEDIAN(IF(Ownership[STATE]=B46,Ownership[GROSS/SF]))}
B47: DC | C47: =SUMIFS(Sold[GROSS],Sold[STATE],B47,Sold[GOV OCCP],">="&0.5)+SUMIFS(Ownership[GROSS],Ownership[STATE],B47,Ownership[OCCP],">="&50) | D47: =COUNTIFS(Sold[GROSS],">"&0,Sold[STATE],B47,Sold[GOV OCCP],">="&0.5)+COUNTIFS(Ownership[GROSS],">"&0,Ownership[STATE],B47,Ownership[OCCP],">="&50) | E47: =C47/D47 | F47: =SUMIFS(Sold[RBA],Sold[STATE],B47,Sold[GROSS],">"&0,Sold[GOV OCCP],">="&0.5)+SUMIFS(Ownership[SF LEASED],Ownership[STATE],B47,Ownership[GROSS],">"&0,Ownership[OCCP],">="&50) | G47: =F47/D47 | H47: =C47/F47 | I47: {=PERCENTILE(IF(Ownership[STATE]=B47,Ownership[GROSS/SF]),0.75)} | J47: {=PERCENTILE(IF(Ownership[STATE]=B47,Ownership[GROSS/SF]),0.25)} | K47: {=MEDIAN(IF(Ownership[STATE]=B47,Ownership[GROSS/SF]))}
B48: FL | C48: =SUMIFS(Sold[GROSS],Sold[STATE],B48,Sold[GOV OCCP],">="&0.5)+SUMIFS(Ownership[GROSS],Ownership[STATE],B48,Ownership[OCCP],">="&50) | D48: =COUNTIFS(Sold[GROSS],">"&0,Sold[STATE],B48,Sold[GOV OCCP],">="&0.5)+COUNTIFS(Ownership[GROSS],">"&0,Ownership[STATE],B48,Ownership[OCCP],">="&50) | E48: =C48/D48 | F48: =SUMIFS(Sold[RBA],Sold[STATE],B48,Sold[GROSS],">"&0,Sold[GOV OCCP],">="&0.5)+SUMIFS(Ownership[SF LEASED],Ownership[STATE],B48,Ownership[GROSS],">"&0,Ownership[OCCP],">="&50) | G48: =F48/D48 | H48: =C48/F48 | I48: {=PERCENTILE(IF(Ownership[STATE]=B48,Ownership[GROSS/SF]),0.75)} | J48: {=PERCENTILE(IF(Ownership[STATE]=B48,Ownership[GROSS/SF]),0.25)} | K48: {=MEDIAN(IF(Ownership[STATE]=B48,Ownership[GROSS/SF]))}
B49: GA | C49: =SUMIFS(Sold[GROSS],Sold[STATE],B49,Sold[GOV OCCP],">="&0.5)+SUMIFS(Ownership[GROSS],Ownership[STATE],B49,Ownership[OCCP],">="&50) | D49: =COUNTIFS(Sold[GROSS],">"&0,Sold[STATE],B49,Sold[GOV OCCP],">="&0.5)+COUNTIFS(Ownership[GROSS],">"&0,Ownership[STATE],B49,Ownership[OCCP],">="&50) | E49: =C49/D49 | F49: =SUMIFS(Sold[RBA],Sold[STATE],B49,Sold[GROSS],">"&0,Sold[GOV OCCP],">="&0.5)+SUMIFS(Ownership[SF LEASED],Ownership[STATE],B49,Ownership[GROSS],">"&0,Ownership[OCCP],">="&50) | G49: =F49/D49 | H49: =C49/F49 | I49: {=PERCENTILE(IF(Ownership[STATE]=B49,Ownership[GROSS/SF]),0.75)} | J49: {=PERCENTILE(IF(Ownership[STATE]=B49,Ownership[GROSS/SF]),0.25)} | K49: {=MEDIAN(IF(Ownership[STATE]=B49,Ownership[GROSS/SF]))}
B50: HI | C50: =SUMIFS(Sold[GROSS],Sold[STATE],B50,Sold[GOV OCCP],">="&0.5)+SUMIFS(Ownership[GROSS],Ownership[STATE],B50,Ownership[OCCP],">="&50) | D50: =COUNTIFS(Sold[GROSS],">"&0,Sold[STATE],B50,Sold[GOV OCCP],">="&0.5)+COUNTIFS(Ownership[GROSS],">"&0,Ownership[STATE],B50,Ownership[OCCP],">="&50) | E50: =C50/D50 | F50: =SUMIFS(Sold[RBA],Sold[STATE],B50,Sold[GROSS],">"&0,Sold[GOV OCCP],">="&0.5)+SUMIFS(Ownership[SF LEASED],Ownership[STATE],B50,Ownership[GROSS],">"&0,Ownership[OCCP],">="&50) | G50: =F50/D50 | H50: =C50/F50 | I50: {=PERCENTILE(IF(Ownership[STATE]=B50,Ownership[GROSS/SF]),0.75)} | J50: {=PERCENTILE(IF(Ownership[STATE]=B50,Ownership[GROSS/SF]),0.25)} | K50: {=MEDIAN(IF(Ownership[STATE]=B50,Ownership[GROSS/SF]))}
B51: ID | C51: =SUMIFS(Sold[GROSS],Sold[STATE],B51,Sold[GOV OCCP],">="&0.5)+SUMIFS(Ownership[GROSS],Ownership[STATE],B51,Ownership[OCCP],">="&50) | D51: =COUNTIFS(Sold[GROSS],">"&0,Sold[STATE],B51,Sold[GOV OCCP],">="&0.5)+COUNTIFS(Ownership[GROSS],">"&0,Ownership[STATE],B51,Ownership[OCCP],">="&50) | E51: =C51/D51 | F51: =SUMIFS(Sold[RBA],Sold[STATE],B51,Sold[GROSS],">"&0,Sold[GOV OCCP],">="&0.5)+SUMIFS(Ownership[SF LEASED],Ownership[STATE],B51,Ownership[GROSS],">"&0,Ownership[OCCP],">="&50) | G51: =F51/D51 | H51: =C51/F51 | I51: {=PERCENTILE(IF(Ownership[STATE]=B51,Ownership[GROSS/SF]),0.75)} | J51: {=PERCENTILE(IF(Ownership[STATE]=B51,Ownership[GROSS/SF]),0.25)} | K51: {=MEDIAN(IF(Ownership[STATE]=B51,Ownership[GROSS/SF]))}
B52: IL | C52: =SUMIFS(Sold[GROSS],Sold[STATE],B52,Sold[GOV OCCP],">="&0.5)+SUMIFS(Ownership[GROSS],Ownership[STATE],B52,Ownership[OCCP],">="&50) | D52: =COUNTIFS(Sold[GROSS],">"&0,Sold[STATE],B52,Sold[GOV OCCP],">="&0.5)+COUNTIFS(Ownership[GROSS],">"&0,Ownership[STATE],B52,Ownership[OCCP],">="&50) | E52: =C52/D52 | F52: =SUMIFS(Sold[RBA],Sold[STATE],B52,Sold[GROSS],">"&0,Sold[GOV OCCP],">="&0.5)+SUMIFS(Ownership[SF LEASED],Ownership[STATE],B52,Ownership[GROSS],">"&0,Ownership[OCCP],">="&50) | G52: =F52/D52 | H52: =C52/F52 | I52: {=PERCENTILE(IF(Ownership[STATE]=B52,Ownership[GROSS/SF]),0.75)} | J52: {=PERCENTILE(IF(Ownership[STATE]=B52,Ownership[GROSS/SF]),0.25)} | K52: {=MEDIAN(IF(Ownership[STATE]=B52,Ownership[GROSS/SF]))}
B53: IN | C53: =SUMIFS(Sold[GROSS],Sold[STATE],B53,Sold[GOV OCCP],">="&0.5)+SUMIFS(Ownership[GROSS],Ownership[STATE],B53,Ownership[OCCP],">="&50) | D53: =COUNTIFS(Sold[GROSS],">"&0,Sold[STATE],B53,Sold[GOV OCCP],">="&0.5)+COUNTIFS(Ownership[GROSS],">"&0,Ownership[STATE],B53,Ownership[OCCP],">="&50) | E53: =C53/D53 | F53: =SUMIFS(Sold[RBA],Sold[STATE],B53,Sold[GROSS],">"&0,Sold[GOV OCCP],">="&0.5)+SUMIFS(Ownership[SF LEASED],Ownership[STATE],B53,Ownership[GROSS],">"&0,Ownership[OCCP],">="&50) | G53: =F53/D53 | H53: =C53/F53 | I53: {=PERCENTILE(IF(Ownership[STATE]=B53,Ownership[GROSS/SF]),0.75)} | J53: {=PERCENTILE(IF(Ownership[STATE]=B53,Ownership[GROSS/SF]),0.25)} | K53: {=MEDIAN(IF(Ownership[STATE]=B53,Ownership[GROSS/SF]))}
B54: IA | C54: =SUMIFS(Sold[GROSS],Sold[STATE],B54,Sold[GOV OCCP],">="&0.5)+SUMIFS(Ownership[GROSS],Ownership[STATE],B54,Ownership[OCCP],">="&50) | D54: =COUNTIFS(Sold[GROSS],">"&0,Sold[STATE],B54,Sold[GOV OCCP],">="&0.5)+COUNTIFS(Ownership[GROSS],">"&0,Ownership[STATE],B54,Ownership[OCCP],">="&50) | E54: =C54/D54 | F54: =SUMIFS(Sold[RBA],Sold[STATE],B54,Sold[GROSS],">"&0,Sold[GOV OCCP],">="&0.5)+SUMIFS(Ownership[SF LEASED],Ownership[STATE],B54,Ownership[GROSS],">"&0,Ownership[OCCP],">="&50) | G54: =F54/D54 | H54: =C54/F54 | I54: {=PERCENTILE(IF(Ownership[STATE]=B54,Ownership[GROSS/SF]),0.75)} | J54: {=PERCENTILE(IF(Ownership[STATE]=B54,Ownership[GROSS/SF]),0.25)} | K54: {=MEDIAN(IF(Ownership[STATE]=B54,Ownership[GROSS/SF]))}
... B89: WY | C89: =SUMIFS(Sold[GROSS],Sold[STATE],B89,Sold[GOV OCCP],">="&0.5)+SUMIFS(Ownership[GROSS],Ownership[STATE],B89,Ownership[OCCP],">="&50) | D89: =COUNTIFS(Sold[GROSS],">"&0,Sold[STATE],B89,Sold[GOV OCCP],">="&0.5)+COUNTIFS(Ownership[GROSS],">"&0,Ownership[STATE],B89,Ownership[OCCP],">="&50) | E89: =C89/D89 | F89: =SUMIFS(Sold[RBA],Sold[STATE],B89,Sold[GROSS],">"&0,Sold[GOV OCCP],">="&0.5)+SUMIFS(Ownership[SF LEASED],Ownership[STATE],B89,Ownership[GROSS],">"&0,Ownership[OCCP],">="&50) | G89: =F89/D89 | H89: =C89/F89 | I89: {=PERCENTILE(IF(Ownership[STATE]=B89,Ownership[GROSS/SF]),0.75)} | J89: {=PERCENTILE(IF(Ownership[STATE]=B89,Ownership[GROSS/SF]),0.25)} | K89: {=MEDIAN(IF(Ownership[STATE]=B89,Ownership[GROSS/SF]))}
A91: 45657 | B91: Year Commenced | C91: Sum of Rent | D91: Count of Rent | E91: Average Rents | F91: Sum of RBA | G91: Average RBA | H91: Average RPSF | I91: Upper Quartile Rent | J91: Lower Quartile Rent | K91: Median Rent PSF | M91: 16 - Case for Renewal
A92: 45291 | B92: 2023 | C92: =SUMIFS(Ownership[GROSS],Ownership[COM],">"&A93,Ownership[COM],"<="&A92,Ownership[OCCP],">="&50) | D92: =COUNTIFS(Ownership[GROSS],">"&0,Ownership[COM],">"&A93,Ownership[COM],"<="&A92,Ownership[OCCP],">="&50) | E92: =C92/D92 | F92: =SUMIFS(Ownership[SF LEASED],Ownership[COM],">"&A93,Ownership[COM],"<="&A92,Ownership[GROSS],">"&0,Ownership[OCCP],">="&50) | G92: =F92/D92 | H92: =C92/F92
A93: =EDATE(A92,-12) | B93: 2022 | C93: =SUMIFS(Ownership[GROSS],Ownership[COM],">"&A94,Ownership[COM],"<="&A93,Ownership[OCCP],">="&50) | D93: =COUNTIFS(Ownership[GROSS],">"&0,Ownership[COM],">"&A94,Ownership[COM],"<="&A93,Ownership[OCCP],">="&50) | E93: =C93/D93 | F93: =SUMIFS(Ownership[SF LEASED],Ownership[COM],">"&A94,Ownership[COM],"<="&A93,Ownership[GROSS],">"&0,Ownership[OCCP],">="&50) | G93: =F93/D93 | H93: =C93/F93
A94: =EDATE(A93,-12) | B94: 2021 | C94: =SUMIFS(Ownership[GROSS],Ownership[COM],">"&A95,Ownership[COM],"<="&A94,Ownership[OCCP],">="&50) | D94: =COUNTIFS(Ownership[GROSS],">"&0,Ownership[COM],">"&A95,Ownership[COM],"<="&A94,Ownership[OCCP],">="&50) | E94: =C94/D94 | F94: =SUMIFS(Ownership[SF LEASED],Ownership[COM],">"&A95,Ownership[COM],"<="&A94,Ownership[GROSS],">"&0,Ownership[OCCP],">="&50) | G94: =F94/D94 | H94: =C94/F94
